<?xml version='1.0' encoding='utf-8'?>
<robot name="p3_ur30_2f140">
  
  
  <link name="world" />
  
  
  <link name="base_link" />
  <link name="base_link_inertia">
    <visual>
      <origin rpy="0.0 0.0 3.141592653589793" xyz="0.0 0.0 0.0" />
      <geometry>
        <mesh filename="package://merge/mesh/ur20/visual/base.dae" />
      </geometry>
    </visual>
    <collision>
      <origin rpy="0.0 0.0 3.141592653589793" xyz="0.0 0.0 0.0" />
      <geometry>
        <mesh filename="package://merge/mesh/ur20/collision/base.stl" />
      </geometry>
    </collision>
    <inertial>
      <mass value="4.0" />
      <origin rpy="0 0 0" xyz="0 0 0" />
      <inertia ixx="0.0061063308908" ixy="0.0" ixz="0.0" iyy="0.0061063308908" iyz="0.0" izz="0.01125" />
    </inertial>
  </link>
  <link name="shoulder_link">
    <visual>
      <origin rpy="0.0 0.0 3.141592653589793" xyz="0.0 0.0 0.0" />
      <geometry>
        <mesh filename="package://merge/mesh/ur20/visual/shoulder.dae" />
      </geometry>
    </visual>
    <collision>
      <origin rpy="0.0 0.0 3.141592653589793" xyz="0.0 0.0 0.0" />
      <geometry>
        <mesh filename="package://merge/mesh/ur20/collision/shoulder.stl" />
      </geometry>
    </collision>
    <inertial>
      <mass value="16.343" />
      <origin rpy="1.570796326794897 0 0" xyz="-0.0001 -0.0069 -0.06" />
      <inertia ixx="0.03351" ixy="2e-05" ixz="-1e-05" iyy="0.03374" iyz="0.00374" izz="0.021" />
    </inertial>
  </link>
  <link name="upper_arm_link">
    <visual>
      <origin rpy="1.5707963267948966 0.0 -1.5707963267948966" xyz="0.0 0.0 0.26" />
      <geometry>
        <mesh filename="package://merge/mesh/ur30/visual/upperarm.dae" />
      </geometry>
    </visual>
    <collision>
      <origin rpy="1.5707963267948966 0.0 -1.5707963267948966" xyz="0.0 0.0 0.26" />
      <geometry>
        <mesh filename="package://merge/mesh/ur30/collision/upperarm.stl" />
      </geometry>
    </collision>
    <inertial>
      <mass value="28.542" />
      <origin rpy="0 0 0" xyz="-0.2476 0.0 0.2103" />
      <inertia ixx="0.02796" ixy="-0.0001" ixz="-0.0072" iyy="0.47558" iyz="3e-05" izz="0.47635" />
    </inertial>
  </link>
  <link name="forearm_link">
    <visual>
      <origin rpy="1.5707963267948966 0.0 -1.5707963267948966" xyz="0.0 0.0 0.043" />
      <geometry>
        <mesh filename="package://merge/mesh/ur30/visual/forearm.dae" />
      </geometry>
    </visual>
    <collision>
      <origin rpy="1.5707963267948966 0.0 -1.5707963267948966" xyz="0.0 0.0 0.043" />
      <geometry>
        <mesh filename="package://merge/mesh/ur30/collision/forearm.stl" />
      </geometry>
    </collision>
    <inertial>
      <mass value="7.156" />
      <origin rpy="0 0 0" xyz="-0.278 0.0 0.0629" />
      <inertia ixx="0.01091" ixy="6e-05" ixz="0.01012" iyy="0.1206" iyz="1e-05" izz="0.11714" />
    </inertial>
  </link>
  <link name="wrist_1_link">
    <visual>
      <origin rpy="1.5707963267948966 0.0 0.0" xyz="0.0 0.0 -0.0775" />
      <geometry>
        <mesh filename="package://merge/mesh/ur20/visual/wrist1.dae" />
      </geometry>
    </visual>
    <collision>
      <origin rpy="1.5707963267948966 0.0 0.0" xyz="0.0 0.0 -0.0775" />
      <geometry>
        <mesh filename="package://merge/mesh/ur20/collision/wrist1.stl" />
      </geometry>
    </collision>
    <inertial>
      <mass value="3.054" />
      <origin rpy="1.570796326794897 0 0" xyz="0.0 -0.0353 -0.0048" />
      <inertia ixx="0.00609" ixy="-1e-05" ixz="0.0" iyy="0.00245" iyz="0.00083" izz="0.00579" />
    </inertial>
  </link>
  <link name="wrist_2_link">
    <visual>
      <origin rpy="0.0 0.0 0.0" xyz="0.0 0.0 -0.0749" />
      <geometry>
        <mesh filename="package://merge/mesh/ur20/visual/wrist2.dae" />
      </geometry>
    </visual>
    <collision>
      <origin rpy="0.0 0.0 0.0" xyz="0.0 0.0 -0.0749" />
      <geometry>
        <mesh filename="package://merge/mesh/ur20/collision/wrist2.stl" />
      </geometry>
    </collision>
    <inertial>
      <mass value="3.126" />
      <origin rpy="-1.570796326794897 0 0" xyz="0.0 0.0341 -0.0046" />
      <inertia ixx="0.00389" ixy="1e-05" ixz="0.0" iyy="0.00219" iyz="-0.00045" izz="0.00363" />
    </inertial>
  </link>
  <link name="wrist_3_link">
    <visual>
      <origin rpy="1.5707963267948966 0.0 0.0" xyz="0.0 0.0 -0.07" />
      <geometry>
        <mesh filename="package://merge/mesh/ur20/visual/wrist3.dae" />
      </geometry>
    </visual>
    <collision>
      <origin rpy="1.5707963267948966 0.0 0.0" xyz="0.0 0.0 -0.07" />
      <geometry>
        <mesh filename="package://merge/mesh/ur20/collision/wrist3.stl" />
      </geometry>
    </collision>
    <inertial>
      <mass value="0.926" />
      <origin rpy="0 0 0" xyz="0.0 0.0 -0.0293" />
      <inertia ixx="0.00117" ixy="0.0" ixz="0.0" iyy="0.00118" iyz="0.0" izz="0.00084" />
    </inertial>
  </link>
  
  <joint name="base_joint" type="fixed">
    <origin rpy="0 0 0" xyz="0 0 0" />
    <parent link="world" />
    <child link="base_link" />
  </joint>
  
  <joint name="base_link-base_link_inertia" type="fixed">
    <parent link="base_link" />
    <child link="base_link_inertia" />
    
    <origin rpy="0 0 3.141592653589793" xyz="0 0 0" />
  </joint>
  <joint name="shoulder_pan_joint" type="revolute">
    <parent link="base_link_inertia" />
    <child link="shoulder_link" />
    <origin rpy="0 0 0" xyz="0 0 0.2363" />
    <axis xyz="0 0 1" />
    <limit effort="738.0" lower="-6.283185307179586" upper="6.283185307179586" velocity="2.0943951023931953" />
    <dynamics damping="0" friction="0" />
  </joint>
  <joint name="shoulder_lift_joint" type="revolute">
    <parent link="shoulder_link" />
    <child link="upper_arm_link" />
    <origin rpy="1.570796327 0 0" xyz="0 0 0" />
    <axis xyz="0 0 1" />
    <limit effort="738.0" lower="-6.283185307179586" upper="6.283185307179586" velocity="2.0943951023931953" />
    <dynamics damping="0" friction="0" />
  </joint>
  <joint name="elbow_joint" type="revolute">
    <parent link="upper_arm_link" />
    <child link="forearm_link" />
    <origin rpy="0 0 0" xyz="-0.637 0 0" />
    <axis xyz="0 0 1" />
    <limit effort="433.0" lower="-3.141592653589793" upper="3.141592653589793" velocity="2.6179938779914944" />
    <dynamics damping="0" friction="0" />
  </joint>
  <joint name="wrist_1_joint" type="revolute">
    <parent link="forearm_link" />
    <child link="wrist_1_link" />
    <origin rpy="0 0 0" xyz="-0.5037 0 0.201" />
    <axis xyz="0 0 1" />
    <limit effort="107.0" lower="-6.283185307179586" upper="6.283185307179586" velocity="3.6651914291880923" />
    <dynamics damping="0" friction="0" />
  </joint>
  <joint name="wrist_2_joint" type="revolute">
    <parent link="wrist_1_link" />
    <child link="wrist_2_link" />
    <origin rpy="1.570796327 0 0" xyz="0 -0.1593 -3.267297616249225e-11" />
    <axis xyz="0 0 1" />
    <limit effort="107.0" lower="-6.283185307179586" upper="6.283185307179586" velocity="3.6651914291880923" />
    <dynamics damping="0" friction="0" />
  </joint>
  <joint name="wrist_3_joint" type="revolute">
    <parent link="wrist_2_link" />
    <child link="wrist_3_link" />
    <origin rpy="1.570796326589793 3.141592653589793 3.141592653589793" xyz="0 0.1543 -3.1647459019915597e-11" />
    <axis xyz="0 0 1" />
    <limit effort="107.0" lower="-6.283185307179586" upper="6.283185307179586" velocity="3.6651914291880923" />
    <dynamics damping="0" friction="0" />
  </joint>
  <link name="ft_frame" />
  <joint name="wrist_3_link-ft_frame" type="fixed">
    <parent link="wrist_3_link" />
    <child link="ft_frame" />
    <origin rpy="3.141592653589793 0 0" xyz="0 0 0" />
  </joint>
  
  <link name="base" />
  <joint name="base_link-base_fixed_joint" type="fixed">
    
    <origin rpy="0 0 3.141592653589793" xyz="0 0 0" />
    <parent link="base_link" />
    <child link="base" />
  </joint>
  
  <link name="flange" />
  <joint name="wrist_3-flange" type="fixed">
    <parent link="wrist_3_link" />
    <child link="flange" />
    <origin rpy="0 -1.5707963267948966 -1.5707963267948966" xyz="0 0 0" />
  </joint>
  
  <link name="tool0" />
  <joint name="flange-tool0" type="fixed">
    
    <origin rpy="1.5707963267948966 0 1.5707963267948966" xyz="0 0 0" />
    <parent link="flange" />
    <child link="tool0" />
  </joint>
<joint name="tool0_to_gripper" type="fixed"><parent link="tool0" /><child link="robotiq_base_link" /><origin xyz="0 0 0" rpy="0 0 0" /></joint><ros2_control name="RobotiqGripperHardwareInterface" type="system">
    
    <hardware>
      <plugin>mock_components/GenericSystem</plugin>
      <param name="mock_sensor_commands">False</param>
      <param name="state_following_offset">0.0</param>
    </hardware>
    
    
    <joint name="finger_joint">
      <command_interface name="position" />
      <state_interface name="position">
        <param name="initial_value">0.695</param>
      </state_interface>
      <state_interface name="velocity" />
    </joint>
    <joint name="left_inner_knuckle_joint">
      <state_interface name="position" />
      <state_interface name="velocity" />
    </joint>
    <joint name="left_inner_finger_joint">
      <state_interface name="position" />
      <state_interface name="velocity" />
    </joint>
    <joint name="right_outer_knuckle_joint">
      <state_interface name="position" />
      <state_interface name="velocity" />
    </joint>
    <joint name="right_inner_knuckle_joint">
      <state_interface name="position" />
      <state_interface name="velocity" />
    </joint>
    <joint name="right_inner_finger_joint">
      <state_interface name="position" />
      <state_interface name="velocity" />
    </joint>
    <gpio name="reactivate_gripper">
      <command_interface name="reactivate_gripper_cmd" />
      <command_interface name="reactivate_gripper_response" />
    </gpio>
  </ros2_control>
  
  <link name="robotiq_base_link" />
  <link name="robotiq_140_base_link">
    <inertial>
      <origin rpy="0 0 0" xyz="8.625E-08 -4.6583E-06 0.03145" />
      <mass value="0.22652" />
      <inertia ixx="0.00020005" ixy="-4.2442E-10" ixz="-2.9069E-10" iyy="0.00017832" iyz="-3.4402E-08" izz="0.00013478" />
    </inertial>
    <visual>
      <origin rpy="0 0 0" xyz="0 0 0" />
      <geometry>
        <mesh filename="package://merge/mesh/2f-140/visual/robotiq_2f_140_base_link.stl" />
      </geometry>
      <material name="">
        <color rgba="0.1 0.1 0.1 1" />
      </material>
    </visual>
    <collision>
      <origin rpy="0 0 0" xyz="0 0 0" />
      <geometry>
        <mesh filename="package://merge/mesh/2f-140/collision/robotiq_2f_140_base_link.stl" />
      </geometry>
    </collision>
  </link>
  <joint name="robotiq_140_base_joint" type="fixed">
    <parent link="robotiq_base_link" />
    <child link="robotiq_140_base_link" />
    <origin rpy="0 0 0" xyz="0 0 0" />
  </joint>
  <link name="left_outer_knuckle">
    <inertial>
      <origin rpy="0 0 0" xyz="-0.000200000000003065 0.0199435877845359 0.0292245259211331" />
      <mass value="0.00853198276973456" />
      <inertia ixx="2.89328108496468E-06" ixy="-1.57935047237397E-19" ixz="-1.93980378593255E-19" iyy="1.86719750325683E-06" iyz="-1.21858577871576E-06" izz="1.21905238907251E-06" />
    </inertial>
    <visual>
      <origin rpy="0 0 0" xyz="0 0 0" />
      <geometry>
        <mesh filename="package://merge/mesh/2f-140/visual/robotiq_2f_140_outer_knuckle.stl" />
      </geometry>
      <material name="">
        <color rgba="0.792156862745098 0.819607843137255 0.933333333333333 1" />
      </material>
    </visual>
    <collision>
      <origin rpy="0 0 0" xyz="0 0 0" />
      <geometry>
        <mesh filename="package://merge/mesh/2f-140/collision/robotiq_2f_140_outer_knuckle.stl" />
      </geometry>
    </collision>
  </link>
  <link name="left_outer_finger">
    <inertial>
      <origin rpy="0 0 0" xyz="0.00030115855001899 0.0373907951953854 -0.0208027427000385" />
      <mass value="0.022614240507152" />
      <inertia ixx="1.52518312458174E-05" ixy="9.76583423954399E-10" ixz="-5.43838577022588E-10" iyy="6.17694243867776E-06" iyz="6.78636130740228E-06" izz="1.16494917907219E-05" />
    </inertial>
    <visual>
      <origin rpy="0 0 0" xyz="0 0 0" />
      <geometry>
        <mesh filename="package://merge/mesh/2f-140/visual/robotiq_2f_140_outer_finger.stl" />
      </geometry>
      <material name="">
        <color rgba="0.1 0.1 0.1 1" />
      </material>
    </visual>
    <collision>
      <origin rpy="0 0 0" xyz="0 0 0" />
      <geometry>
        <mesh filename="package://merge/mesh/2f-140/collision/robotiq_2f_140_outer_finger.stl" />
      </geometry>
    </collision>
  </link>
  <link name="left_inner_finger">
    <inertial>
      <origin rpy="0 0 0" xyz="0.000299999999999317 0.0160078233491243 -0.0136945669206257" />
      <mass value="0.0104003125914103" />
      <inertia ixx="2.71909453810972E-06" ixy="1.35402465472579E-21" ixz="-7.1817349065269E-22" iyy="7.69100314106116E-07" iyz="6.74715432769696E-07" izz="2.30315190420171E-06" />
    </inertial>
    <visual>
      <origin rpy="0 0 0" xyz="0 0 0" />
      <geometry>
        <mesh filename="package://merge/mesh/2f-140/visual/robotiq_2f_140_inner_finger.stl" />
      </geometry>
      <material name="">
        <color rgba="0.1 0.1 0.1 1" />
      </material>
    </visual>
    <collision>
      <origin rpy="0 0 0" xyz="0 0 0" />
      <geometry>
        <mesh filename="package://merge/mesh/2f-140/collision/robotiq_2f_140_inner_finger.stl" />
      </geometry>
    </collision>
  </link>
  <link name="left_inner_finger_pad">
    <visual>
      <origin rpy="0 0 0" xyz="0 0 0" />
      <geometry>
        <box size="0.027 0.065 0.0075" />
      </geometry>
      <material name="">
        <color rgba="0.9 0.9 0.9 1" />
      </material>
    </visual>
    <collision>
      <origin rpy="0 0 0" xyz="0 0 0" />
      <geometry>
        <box size="0.03 0.07 0.0075" />
      </geometry>
      <material name="">
        <color rgba="0.9 0.0 0.0 1" />
      </material>
    </collision>
  </link>
  <link name="left_inner_knuckle">
    <inertial>
      <origin rpy="0 0 0" xyz="0.000123011831763771 0.0507850843201817 0.00103968640075166" />
      <mass value="0.0271177346495152" />
      <inertia ixx="2.61910379223783E-05" ixy="-2.43616858946494E-07" ixz="-6.37789906117123E-09" iyy="2.8270243746167E-06" iyz="-5.37200748039765E-07" izz="2.83695868220296E-05" />
    </inertial>
    <visual>
      <origin rpy="0 0 0" xyz="0 0 0" />
      <geometry>
        <mesh filename="package://merge/mesh/2f-140/visual/robotiq_2f_140_inner_knuckle.stl" />
      </geometry>
      <material name="">
        <color rgba="0.1 0.1 0.1 1" />
      </material>
    </visual>
    <collision>
      <origin rpy="0 0 0" xyz="0 0 0" />
      <geometry>
        <mesh filename="package://merge/mesh/2f-140/collision/robotiq_2f_140_inner_knuckle.stl" />
      </geometry>
    </collision>
  </link>
  <link name="right_outer_knuckle">
    <inertial>
      <origin rpy="0 0 0" xyz="-0.000200000000003065 0.0199435877845359 0.0292245259211331" />
      <mass value="0.00853198276973456" />
      <inertia ixx="2.89328108496468E-06" ixy="-1.57935047237397E-19" ixz="-1.93980378593255E-19" iyy="1.86719750325683E-06" iyz="-1.21858577871576E-06" izz="1.21905238907251E-06" />
    </inertial>
    <visual>
      <origin rpy="0 0 0" xyz="0 0 0" />
      <geometry>
        <mesh filename="package://merge/mesh/2f-140/visual/robotiq_2f_140_outer_knuckle.stl" />
      </geometry>
      <material name="">
        <color rgba="0.792156862745098 0.819607843137255 0.933333333333333 1" />
      </material>
    </visual>
    <collision>
      <origin rpy="0 0 0" xyz="0 0 0" />
      <geometry>
        <mesh filename="package://merge/mesh/2f-140/collision/robotiq_2f_140_outer_knuckle.stl" />
      </geometry>
    </collision>
  </link>
  <link name="right_outer_finger">
    <inertial>
      <origin rpy="0 0 0" xyz="0.00030115855001899 0.0373907951953854 -0.0208027427000385" />
      <mass value="0.022614240507152" />
      <inertia ixx="1.52518312458174E-05" ixy="9.76583423954399E-10" ixz="-5.43838577022588E-10" iyy="6.17694243867776E-06" iyz="6.78636130740228E-06" izz="1.16494917907219E-05" />
    </inertial>
    <visual>
      <origin rpy="0 0 0" xyz="0 0 0" />
      <geometry>
        <mesh filename="package://merge/mesh/2f-140/visual/robotiq_2f_140_outer_finger.stl" />
      </geometry>
      <material name="">
        <color rgba="0.1 0.1 0.1 1" />
      </material>
    </visual>
    <collision>
      <origin rpy="0 0 0" xyz="0 0 0" />
      <geometry>
        <mesh filename="package://merge/mesh/2f-140/collision/robotiq_2f_140_outer_finger.stl" />
      </geometry>
    </collision>
  </link>
  <link name="right_inner_finger">
    <inertial>
      <origin rpy="0 0 0" xyz="0.000299999999999317 0.0160078233491243 -0.0136945669206257" />
      <mass value="0.0104003125914103" />
      <inertia ixx="2.71909453810972E-06" ixy="1.35402465472579E-21" ixz="-7.1817349065269E-22" iyy="7.69100314106116E-07" iyz="6.74715432769696E-07" izz="2.30315190420171E-06" />
    </inertial>
    <visual>
      <origin rpy="0 0 0" xyz="0 0 0" />
      <geometry>
        <mesh filename="package://merge/mesh/2f-140/visual/robotiq_2f_140_inner_finger.stl" />
      </geometry>
      <material name="">
        <color rgba="0.1 0.1 0.1 1" />
      </material>
    </visual>
    <collision>
      <origin rpy="0 0 0" xyz="0 0 0" />
      <geometry>
        <mesh filename="package://merge/mesh/2f-140/collision/robotiq_2f_140_inner_finger.stl" />
      </geometry>
    </collision>
  </link>
  <link name="right_inner_finger_pad">
    <visual>
      <origin rpy="0 0 0" xyz="0 0 0" />
      <geometry>
        <box size="0.027 0.065 0.0075" />
      </geometry>
      <material name="">
        <color rgba="0.9 0.9 0.9 1" />
      </material>
    </visual>
    <collision>
      <origin rpy="0 0 0" xyz="0 0 0" />
      <geometry>
        <box size="0.03 0.07 0.0075" />
      </geometry>
      <material name="">
        <color rgba="0.9 0.0 0.0 1" />
      </material>
    </collision>
  </link>
  <link name="right_inner_knuckle">
    <inertial>
      <origin rpy="0 0 0" xyz="0.000123011831763771 0.0507850843201817 0.00103968640075166" />
      <mass value="0.0271177346495152" />
      <inertia ixx="2.61910379223783E-05" ixy="-2.43616858946494E-07" ixz="-6.37789906117123E-09" iyy="2.8270243746167E-06" iyz="-5.37200748039765E-07" izz="2.83695868220296E-05" />
    </inertial>
    <visual>
      <origin rpy="0 0 0" xyz="0 0 0" />
      <geometry>
        <mesh filename="package://merge/mesh/2f-140/visual/robotiq_2f_140_inner_knuckle.stl" />
      </geometry>
      <material name="">
        <color rgba="0.1 0.1 0.1 1" />
      </material>
    </visual>
    <collision>
      <origin rpy="0 0 0" xyz="0 0 0" />
      <geometry>
        <mesh filename="package://merge/mesh/2f-140/collision/robotiq_2f_140_inner_knuckle.stl" />
      </geometry>
    </collision>
  </link>
  <joint name="finger_joint" type="revolute">
    <origin rpy="2.2957963267948966 0 0" xyz="0 -0.030601 0.054905" />
    <parent link="robotiq_140_base_link" />
    <child link="left_outer_knuckle" />
    <axis xyz="-1 0 0" />
    <limit effort="1000" lower="0" upper="0.7" velocity="2.0" />
  </joint>
  <joint name="left_outer_finger_joint" type="fixed">
    <origin rpy="0 0 0" xyz="0 0.01821998610742 0.0260018192872234" />
    <parent link="left_outer_knuckle" />
    <child link="left_outer_finger" />
    <axis xyz="1 0 0" />
  </joint>
  <joint name="left_inner_knuckle_joint" type="revolute">
    <origin rpy="2.2957963267948966 0 0.0" xyz="0 -0.0127 0.06142" />
    <parent link="robotiq_140_base_link" />
    <child link="left_inner_knuckle" />
    <axis xyz="1 0 0" />
    <limit effort="1000" lower="-0.8757" upper="0.8757" velocity="2.0" />
    <mimic joint="finger_joint" multiplier="-1" offset="0" />
  </joint>
  <joint name="left_inner_finger_joint" type="revolute">
    <origin rpy="-0.725 0 0" xyz="0 0.0817554015893473 -0.0282203446692936" />
    <parent link="left_outer_finger" />
    <child link="left_inner_finger" />
    <axis xyz="1 0 0" />
    <limit effort="1000" lower="-0.8757" upper="0.8757" velocity="2.0" />
    <mimic joint="finger_joint" multiplier="1" offset="0" />
  </joint>
  <joint name="left_inner_finger_pad_joint" type="fixed">
    <origin rpy="0 0 0" xyz="0 0.0457554015893473 -0.0272203446692936" />
    <parent link="left_inner_finger" />
    <child link="left_inner_finger_pad" />
    <axis xyz="0 0 1" />
  </joint>
  <joint name="right_outer_knuckle_joint" type="revolute">
    <origin rpy="2.2957963267948966 0 3.141592653589793" xyz="0 0.030601 0.054905" />
    <parent link="robotiq_140_base_link" />
    <child link="right_outer_knuckle" />
    <axis xyz="1 0 0" />
    <limit effort="1000" lower="-0.725" upper="0.725" velocity="2.0" />
    <mimic joint="finger_joint" multiplier="-1" offset="0" />
  </joint>
  <joint name="right_outer_finger_joint" type="fixed">
    <origin rpy="0 0 0" xyz="0 0.01821998610742 0.0260018192872234" />
    <parent link="right_outer_knuckle" />
    <child link="right_outer_finger" />
    <axis xyz="1 0 0" />
  </joint>
  <joint name="right_inner_knuckle_joint" type="revolute">
    <origin rpy="2.2957963267948966 0 -3.141592653589793" xyz="0 0.0127 0.06142" />
    <parent link="robotiq_140_base_link" />
    <child link="right_inner_knuckle" />
    <axis xyz="1 0 0" />
    <limit effort="1000" lower="-0.8757" upper="0.8757" velocity="2.0" />
    <mimic joint="finger_joint" multiplier="-1" offset="0" />
  </joint>
  <joint name="right_inner_finger_joint" type="revolute">
    <origin rpy="-0.725 0 0" xyz="0 0.0817554015893473 -0.0282203446692936" />
    <parent link="right_outer_finger" />
    <child link="right_inner_finger" />
    <axis xyz="1 0 0" />
    <limit effort="1000" lower="-0.8757" upper="0.8757" velocity="2.0" />
    <mimic joint="finger_joint" multiplier="1" offset="0" />
  </joint>
  <joint name="right_inner_finger_pad_joint" type="fixed">
    <origin rpy="0 0 0" xyz="0 0.0457554015893473 -0.0272203446692936" />
    <parent link="right_inner_finger" />
    <child link="right_inner_finger_pad" />
    <axis xyz="0 0 1" />
  </joint>
</robot>