<?xml version='1.0' encoding='utf-8'?>
<robot name="p4_ur30_epick">
  
  
  <link name="world" />
  
  
  <link name="base_link" />
  <link name="base_link_inertia">
    <visual>
      <origin rpy="0.0 0.0 3.141592653589793" xyz="0.0 0.0 0.0" />
      <geometry>
        <mesh filename="package://merge/mesh/ur20/visual/base.dae" />
      </geometry>
    </visual>
    <collision>
      <origin rpy="0.0 0.0 3.141592653589793" xyz="0.0 0.0 0.0" />
      <geometry>
        <mesh filename="package://merge/mesh/ur20/collision/base.stl" />
      </geometry>
    </collision>
    <inertial>
      <mass value="4.0" />
      <origin rpy="0 0 0" xyz="0 0 0" />
      <inertia ixx="0.0061063308908" ixy="0.0" ixz="0.0" iyy="0.0061063308908" iyz="0.0" izz="0.01125" />
    </inertial>
  </link>
  <link name="shoulder_link">
    <visual>
      <origin rpy="0.0 0.0 3.141592653589793" xyz="0.0 0.0 0.0" />
      <geometry>
        <mesh filename="package://merge/mesh/ur20/visual/shoulder.dae" />
      </geometry>
    </visual>
    <collision>
      <origin rpy="0.0 0.0 3.141592653589793" xyz="0.0 0.0 0.0" />
      <geometry>
        <mesh filename="package://merge/mesh/ur20/collision/shoulder.stl" />
      </geometry>
    </collision>
    <inertial>
      <mass value="16.343" />
      <origin rpy="1.570796326794897 0 0" xyz="-0.0001 -0.0069 -0.06" />
      <inertia ixx="0.03351" ixy="2e-05" ixz="-1e-05" iyy="0.03374" iyz="0.00374" izz="0.021" />
    </inertial>
  </link>
  <link name="upper_arm_link">
    <visual>
      <origin rpy="1.5707963267948966 0.0 -1.5707963267948966" xyz="0.0 0.0 0.26" />
      <geometry>
        <mesh filename="package://merge/mesh/ur30/visual/upperarm.dae" />
      </geometry>
    </visual>
    <collision>
      <origin rpy="1.5707963267948966 0.0 -1.5707963267948966" xyz="0.0 0.0 0.26" />
      <geometry>
        <mesh filename="package://merge/mesh/ur30/collision/upperarm.stl" />
      </geometry>
    </collision>
    <inertial>
      <mass value="28.542" />
      <origin rpy="0 0 0" xyz="-0.2476 0.0 0.2103" />
      <inertia ixx="0.02796" ixy="-0.0001" ixz="-0.0072" iyy="0.47558" iyz="3e-05" izz="0.47635" />
    </inertial>
  </link>
  <link name="forearm_link">
    <visual>
      <origin rpy="1.5707963267948966 0.0 -1.5707963267948966" xyz="0.0 0.0 0.043" />
      <geometry>
        <mesh filename="package://merge/mesh/ur30/visual/forearm.dae" />
      </geometry>
    </visual>
    <collision>
      <origin rpy="1.5707963267948966 0.0 -1.5707963267948966" xyz="0.0 0.0 0.043" />
      <geometry>
        <mesh filename="package://merge/mesh/ur30/collision/forearm.stl" />
      </geometry>
    </collision>
    <inertial>
      <mass value="7.156" />
      <origin rpy="0 0 0" xyz="-0.278 0.0 0.0629" />
      <inertia ixx="0.01091" ixy="6e-05" ixz="0.01012" iyy="0.1206" iyz="1e-05" izz="0.11714" />
    </inertial>
  </link>
  <link name="wrist_1_link">
    <visual>
      <origin rpy="1.5707963267948966 0.0 0.0" xyz="0.0 0.0 -0.0775" />
      <geometry>
        <mesh filename="package://merge/mesh/ur20/visual/wrist1.dae" />
      </geometry>
    </visual>
    <collision>
      <origin rpy="1.5707963267948966 0.0 0.0" xyz="0.0 0.0 -0.0775" />
      <geometry>
        <mesh filename="package://merge/mesh/ur20/collision/wrist1.stl" />
      </geometry>
    </collision>
    <inertial>
      <mass value="3.054" />
      <origin rpy="1.570796326794897 0 0" xyz="0.0 -0.0353 -0.0048" />
      <inertia ixx="0.00609" ixy="-1e-05" ixz="0.0" iyy="0.00245" iyz="0.00083" izz="0.00579" />
    </inertial>
  </link>
  <link name="wrist_2_link">
    <visual>
      <origin rpy="0.0 0.0 0.0" xyz="0.0 0.0 -0.0749" />
      <geometry>
        <mesh filename="package://merge/mesh/ur20/visual/wrist2.dae" />
      </geometry>
    </visual>
    <collision>
      <origin rpy="0.0 0.0 0.0" xyz="0.0 0.0 -0.0749" />
      <geometry>
        <mesh filename="package://merge/mesh/ur20/collision/wrist2.stl" />
      </geometry>
    </collision>
    <inertial>
      <mass value="3.126" />
      <origin rpy="-1.570796326794897 0 0" xyz="0.0 0.0341 -0.0046" />
      <inertia ixx="0.00389" ixy="1e-05" ixz="0.0" iyy="0.00219" iyz="-0.00045" izz="0.00363" />
    </inertial>
  </link>
  <link name="wrist_3_link">
    <visual>
      <origin rpy="1.5707963267948966 0.0 0.0" xyz="0.0 0.0 -0.07" />
      <geometry>
        <mesh filename="package://merge/mesh/ur20/visual/wrist3.dae" />
      </geometry>
    </visual>
    <collision>
      <origin rpy="1.5707963267948966 0.0 0.0" xyz="0.0 0.0 -0.07" />
      <geometry>
        <mesh filename="package://merge/mesh/ur20/collision/wrist3.stl" />
      </geometry>
    </collision>
    <inertial>
      <mass value="0.926" />
      <origin rpy="0 0 0" xyz="0.0 0.0 -0.0293" />
      <inertia ixx="0.00117" ixy="0.0" ixz="0.0" iyy="0.00118" iyz="0.0" izz="0.00084" />
    </inertial>
  </link>
  
  <joint name="base_joint" type="fixed">
    <origin rpy="0 0 0" xyz="0 0 0" />
    <parent link="world" />
    <child link="base_link" />
  </joint>
  
  <joint name="base_link-base_link_inertia" type="fixed">
    <parent link="base_link" />
    <child link="base_link_inertia" />
    
    <origin rpy="0 0 3.141592653589793" xyz="0 0 0" />
  </joint>
  <joint name="shoulder_pan_joint" type="revolute">
    <parent link="base_link_inertia" />
    <child link="shoulder_link" />
    <origin rpy="0 0 0" xyz="0 0 0.2363" />
    <axis xyz="0 0 1" />
    <limit effort="738.0" lower="-6.283185307179586" upper="6.283185307179586" velocity="2.0943951023931953" />
    <dynamics damping="0" friction="0" />
  </joint>
  <joint name="shoulder_lift_joint" type="revolute">
    <parent link="shoulder_link" />
    <child link="upper_arm_link" />
    <origin rpy="1.570796327 0 0" xyz="0 0 0" />
    <axis xyz="0 0 1" />
    <limit effort="738.0" lower="-6.283185307179586" upper="6.283185307179586" velocity="2.0943951023931953" />
    <dynamics damping="0" friction="0" />
  </joint>
  <joint name="elbow_joint" type="revolute">
    <parent link="upper_arm_link" />
    <child link="forearm_link" />
    <origin rpy="0 0 0" xyz="-0.637 0 0" />
    <axis xyz="0 0 1" />
    <limit effort="433.0" lower="-3.141592653589793" upper="3.141592653589793" velocity="2.6179938779914944" />
    <dynamics damping="0" friction="0" />
  </joint>
  <joint name="wrist_1_joint" type="revolute">
    <parent link="forearm_link" />
    <child link="wrist_1_link" />
    <origin rpy="0 0 0" xyz="-0.5037 0 0.201" />
    <axis xyz="0 0 1" />
    <limit effort="107.0" lower="-6.283185307179586" upper="6.283185307179586" velocity="3.6651914291880923" />
    <dynamics damping="0" friction="0" />
  </joint>
  <joint name="wrist_2_joint" type="revolute">
    <parent link="wrist_1_link" />
    <child link="wrist_2_link" />
    <origin rpy="1.570796327 0 0" xyz="0 -0.1593 -3.267297616249225e-11" />
    <axis xyz="0 0 1" />
    <limit effort="107.0" lower="-6.283185307179586" upper="6.283185307179586" velocity="3.6651914291880923" />
    <dynamics damping="0" friction="0" />
  </joint>
  <joint name="wrist_3_joint" type="revolute">
    <parent link="wrist_2_link" />
    <child link="wrist_3_link" />
    <origin rpy="1.570796326589793 3.141592653589793 3.141592653589793" xyz="0 0.1543 -3.1647459019915597e-11" />
    <axis xyz="0 0 1" />
    <limit effort="107.0" lower="-6.283185307179586" upper="6.283185307179586" velocity="3.6651914291880923" />
    <dynamics damping="0" friction="0" />
  </joint>
  <link name="ft_frame" />
  <joint name="wrist_3_link-ft_frame" type="fixed">
    <parent link="wrist_3_link" />
    <child link="ft_frame" />
    <origin rpy="3.141592653589793 0 0" xyz="0 0 0" />
  </joint>
  
  <link name="base" />
  <joint name="base_link-base_fixed_joint" type="fixed">
    
    <origin rpy="0 0 3.141592653589793" xyz="0 0 0" />
    <parent link="base_link" />
    <child link="base" />
  </joint>
  
  <link name="flange" />
  <joint name="wrist_3-flange" type="fixed">
    <parent link="wrist_3_link" />
    <child link="flange" />
    <origin rpy="0 -1.5707963267948966 -1.5707963267948966" xyz="0 0 0" />
  </joint>
  
  <link name="tool0" />
  <joint name="flange-tool0" type="fixed">
    
    <origin rpy="1.5707963267948966 0 1.5707963267948966" xyz="0 0 0" />
    <parent link="flange" />
    <child link="tool0" />
  </joint>
<joint name="tool0_to_gripper" type="fixed"><parent link="tool0" /><child link="epick_base_link" /><origin xyz="0 0 0" rpy="0 0 0" /></joint><ros2_control name="epick_driver_ros2_control" type="system">
    <hardware>
      <plugin>epick_driver/EpickGripperHardwareInterface</plugin>
      
      <param name="usb_port">/dev/ttyUSB0</param>
      <param name="baud_rate">115200</param>
      <param name="timeout">0.2</param>
      
      
      <param name="use_dummy">False</param>
      
      <param name="slave_address">0x9</param>
      
      <param name="mode">AdvancedMode</param>
      
      <param name="grip_max_vacuum_pressure">-60</param>
      <param name="grip_min_vacuum_pressure">-10</param>
      <param name="grip_timeout">25.0</param>
      <param name="release_timeout">2.0</param>
    </hardware>
    <gpio name="gripper">
      
      <command_interface name="grip_cmd" />
      
      <state_interface name="grip_cmd" />
      
      <state_interface name="object_detection_status" />
    </gpio>
    
    <joint name="gripper">
      
      <state_interface name="position" />
    </joint>
  </ros2_control>
  
  <link name="epick_base_link" />
  <link name="epick_body">
    <visual>
      
      <origin rpy="0 0 0" xyz="0 0 -0.05115" />
      <geometry>
        <mesh filename="package://merge/mesh/epick/visual/epick_body.stl" scale="0.001 0.001 0.001" />
      </geometry>
      <material name="epick_gray">
        <color rgba="0.25 0.25 0.25 1" />
      </material>
    </visual>
    <collision>
      <origin rpy="0 0 0" xyz="0 0 0" />
      <geometry>
        <cylinder length="0.1023" radius="0.044" />
      </geometry>
    </collision>
  </link>
  <joint name="epick_base_link_to_epick_body" type="fixed">
    <parent link="epick_base_link" />
    <child link="epick_body" />
    <origin rpy="0 0 0" xyz="0 0 0.05115" />
  </joint>
  <link name="epick_suction_cup">
    <visual>
      <origin rpy="0 0 0" xyz="0 0 0" />
      <geometry>
        <cylinder length="0.015" radius="0.012" />
      </geometry>
      <material name="">
        <color rgba="0.25 0.25 0.25 1" />
      </material>
    </visual>
    <collision>
      <origin rpy="0 0 0" xyz="0 0 0" />
      <geometry>
        <cylinder length="0.015" radius="0.012" />
      </geometry>
    </collision>
  </link>
  <joint name="epick_body_to_epick_suction_cup" type="fixed">
    <parent link="epick_body" />
    <child link="epick_suction_cup" />
    <origin rpy="0 0 0" xyz="0 0 0.05865" />
  </joint>
  
  
  <link name="epick_tip" />
  <joint name="epick_suction_cup_to_epick_tip" type="fixed">
    <parent link="epick_suction_cup" />
    <child link="epick_tip" />
    <origin rpy="0 0 0" xyz="0 0 0.0075" />
  </joint>
  
  
  <link name="epick_tcp" />
  <joint name="epick_tip_to_epick_tcp" type="fixed">
    <parent link="epick_tip" />
    <child link="epick_tcp" />
    <origin rpy="0 0 0" xyz="0 0 -0.0" />
  </joint>
  
  <link name="epick_vacuum_state" />
  <joint name="gripper" type="revolute">
    <origin rpy="0 0 0" xyz="0 0 0" />
    <parent link="epick_tcp" />
    <child link="epick_vacuum_state" />
    <limit effort="30" lower="0.0" upper="1.0" velocity="1.0" />
  </joint>
</robot>