<?xml version='1.0' encoding='utf-8'?>
<robot name="p5_crx5ia_2f140">
  <link name="world" />
  <link name="ee_link" />
  
  <link name="base_link">
    <visual>
      <origin rpy="0 0 0" xyz="0 0 0" />
      <geometry>
        <mesh filename="package://merge/mesh/crx5ia/visual/base.dae" />
      </geometry>
    </visual>
    <collision>
      <origin rpy="0 0 0" xyz="0 0 0" />
      <geometry>
        <mesh filename="package://merge/mesh/crx5ia/collision/base.stl" scale="0.001 0.001 0.001" />
      </geometry>
    </collision>
    <inertial>
      <mass value="2.695" />
      <origin xyz="-0.02329 -0.00113 0.04668" />
      <inertia ixx="0.004082061" ixy="0.000281666" ixz="0.001055913" iyy="0.008721822" iyz="4.52295E-05" izz="0.009813918" />
    </inertial>
  </link>
  <link name="J1_link">
    <visual>
      <origin rpy="0 0 0" xyz="0 0 -0.185" />
      <geometry>
        <mesh filename="package://merge/mesh/crx5ia/visual/j1.dae" />
      </geometry>
    </visual>
    <collision>
      <origin rpy="0 0 -1.5707963267948966" xyz="0 0 -0.185" />
      <geometry>
        <mesh filename="package://merge/mesh/crx5ia/collision/j1.stl" scale="0.001 0.001 0.001" />
      </geometry>
    </collision>
    <inertial>
      <mass value="5.173" />
      <origin xyz="-0.00223 -0.04084 -0.03" />
      <inertia ixx="0.027098156" ixy="-0.000166078" ixz="-0.000127776" iyy="0.015731396" iyz="-0.005631899" izz="0.0195838" />
    </inertial>
  </link>
  <link name="J2_link">
    <visual>
      <origin rpy="0 0 0" xyz="-0.0 0 -0.185" />
      <geometry>
        <mesh filename="package://merge/mesh/crx5ia/visual/j2.dae" />
      </geometry>
    </visual>
    <collision>
      <origin rpy="0 0 -1.5707963267948966" xyz="-0.0 0 -0.185" />
      <geometry>
        <mesh filename="package://merge/mesh/crx5ia/collision/j2.stl" scale="0.001 0.001 0.001" />
      </geometry>
    </collision>
    <inertial>
      <mass value="5.014" />
      <origin xyz="0.00013 -0.14378 0.18566" />
      <inertia ixx="0.183168026" ixy="-3.67741E-05" ixz="0.000192371" iyy="0.178671177" iyz="0.01360861" izz="0.013395386" />
    </inertial>
  </link>
  <link name="J3_link">
    <visual>
      <origin rpy="0 0 0" xyz="-0.0 0 -0.595" />
      <geometry>
        <mesh filename="package://merge/mesh/crx5ia/visual/j3.dae" />
      </geometry>
    </visual>
    <collision>
      <origin rpy="0 0 -1.5707963267948966" xyz="-0.0 0 -0.595" />
      <geometry>
        <mesh filename="package://merge/mesh/crx5ia/collision/j3.stl" scale="0.001 0.001 0.001" />
      </geometry>
    </collision>
    <inertial>
      <mass value="3.133" />
      <origin xyz="0.0303 -0.01286 -0.0002" />
      <inertia ixx="0.005769799" ixy="0.001344252" ixz="1.14634E-05" iyy="0.008568956" iyz="1.8629E-06" izz="0.009083218" />
    </inertial>
  </link>
  <link name="J4_link">
    <visual>
      <origin rpy="0 0 0" xyz="-0.0 0 -0.595" />
      <geometry>
        <mesh filename="package://merge/mesh/crx5ia/visual/j4.dae" />
      </geometry>
    </visual>
    <collision>
      <origin rpy="0 0 -1.5707963267948966" xyz="-0.0 0 -0.595" />
      <geometry>
        <mesh filename="package://merge/mesh/crx5ia/collision/j4.stl" scale="0.001 0.001 0.001" />
      </geometry>
    </collision>
    <inertial>
      <mass value="3.508" />
      <origin xyz="0.28287 0.00109 0.00019" />
      <inertia ixx="0.003276324" ixy="-0.00164576" ixz="-1.35414E-05" iyy="0.053727933" iyz="-4.1252E-06" izz="0.053791595" />
    </inertial>
  </link>
  <link name="J5_link">
    <visual>
      <origin rpy="0 0 0" xyz="-0.43 0 -0.595" />
      <geometry>
        <mesh filename="package://merge/mesh/crx5ia/visual/j5.dae" />
      </geometry>
    </visual>
    <collision>
      <origin rpy="0 0 -1.5707963267948966" xyz="-0.43 0 -0.595" />
      <geometry>
        <mesh filename="package://merge/mesh/crx5ia/collision/j5.stl" scale="0.001 0.001 0.001" />
      </geometry>
    </collision>
    <inertial>
      <mass value="2.434" />
      <origin xyz="0.01442 -0.09491 0.00164" />
      <inertia ixx="0.006167974" ixy="-0.001284188" ixz="-2.28931E-05" iyy="0.003922645" iyz="-0.00029073" izz="0.007292078" />
    </inertial>
  </link>
  <link name="J6_link">
    <visual>
      <origin rpy="0 0 0" xyz="-0.43 0.13 -0.595" />
      <geometry>
        <mesh filename="package://merge/mesh/crx5ia/visual/j6.dae" />
      </geometry>
    </visual>
    <collision>
      <origin rpy="0 0 0" xyz="0 0 0" />
      <geometry>
        <mesh filename="package://merge/mesh/crx5ia/collision/j6.stl" scale="0.001 0.001 0.001" />
      </geometry>
    </collision>
    <inertial>
      <mass value="1.272" />
      <origin xyz="0.10028 0.00052 0.00002" />
      <inertia ixx="0.00143989" ixy="1.06324E-05" ixz="-7.92E-08" iyy="0.001354656" iyz="-2.602E-07" izz="0.001399779" />
    </inertial>
  </link>
  
  <joint name="J1" type="revolute">
    <origin rpy="0 0 0" xyz="0 0 0.185" />
    <parent link="base_link" />
    <child link="J1_link" />
    <axis xyz="0 0 1" />
    <limit effort="160" lower="-3.490658503988659" upper="3.490658503988659" velocity="2.6179938779914944" />
  </joint>
  <joint name="J2" type="revolute">
    <origin rpy="0 0 0" xyz="0.0 0 0" />
    <parent link="J1_link" />
    <child link="J2_link" />
    <axis xyz="0 1 0" />
    <limit effort="160" lower="-3.139847324337799" upper="3.139847324337799" velocity="2.6179938779914944" />
  </joint>
  <joint name="J3" type="revolute">
    <origin rpy="0 0 0" xyz="0 0 0.41" />
    <parent link="J2_link" />
    <child link="J3_link" />
    <axis xyz="0 -1 0" />
    <limit effort="160" lower="-1.1868238913561442" upper="4.328416544945937" velocity="3.141592653589793" />
  </joint>
  <joint name="J4" type="revolute">
    <origin rpy="0 0 0" xyz="0 0 0.0" />
    <parent link="J3_link" />
    <child link="J4_link" />
    <axis xyz="-1 0 0" />
    <limit effort="40" lower="-3.3161255787892263" upper="3.3161255787892263" velocity="3.9269908169872414" />
  </joint>
  <joint name="J5" type="revolute">
    <origin rpy="0 0 0" xyz="0.43 0 0" />
    <parent link="J4_link" />
    <child link="J5_link" />
    <axis xyz="0 -1 0" />
    <limit effort="40" lower="-3.139847324337799" upper="3.139847324337799" velocity="3.9269908169872414" />
  </joint>
  <joint name="J6" type="revolute">
    <origin rpy="0 0 0" xyz="0 -0.13 0" />
    <parent link="J5_link" />
    <child link="J6_link" />
    <axis xyz="-1 0 0" />
    <limit effort="40" lower="-3.9269908169872414" upper="3.9269908169872414" velocity="3.9269908169872414" />
  </joint>
  
  <link name="wbase" />
  <joint name="base_link-wbase" type="fixed">
    <origin rpy="0 0 0" xyz="0 0 0.185" />
    <parent link="base_link" />
    <child link="wbase" />
  </joint>
  
  <link name="flange" />
  <joint name="J6-flange" type="fixed">
    <origin rpy="0 0 0" xyz="0.145 0 0" />
    <parent link="J6_link" />
    <child link="flange" />
  </joint>
  
  <joint name="base_joint" type="fixed">
    <origin rpy="0 0 0" xyz="0 0 .75" />
    <parent link="world" />
    <child link="base_link" />
  </joint>
  
  <joint name="child_joint" type="fixed">
    <origin rpy="0 0 0" xyz="0 0 0" />
    <parent link="flange" />
    <child link="ee_link" />
  </joint>
  
  <!-- Tool0 frame definition -->
  <link name="tool0" />
  
  <joint name="flange_to_tool0" type="fixed">
    <parent link="flange" />
    <child link="tool0" />
    <origin xyz="0 0 0" rpy="0 0 0" />
  </joint>
  
  <joint name="tool0_to_gripper" type="fixed">
    <parent link="tool0" />
    <child link="robotiq_base_link" />
    <origin xyz="0 0 0" rpy="0 0 0" />
  </joint>
  
  <ros2_control name="RobotiqGripperHardwareInterface" type="system">
    
    <hardware>
      <plugin>mock_components/GenericSystem</plugin>
      <param name="mock_sensor_commands">False</param>
      <param name="state_following_offset">0.0</param>
    </hardware>
    
    
    <joint name="finger_joint">
      <command_interface name="position" />
      <state_interface name="position">
        <param name="initial_value">0.695</param>
      </state_interface>
      <state_interface name="velocity" />
    </joint>
    <joint name="left_inner_knuckle_joint">
      <state_interface name="position" />
      <state_interface name="velocity" />
    </joint>
    <joint name="left_inner_finger_joint">
      <state_interface name="position" />
      <state_interface name="velocity" />
    </joint>
    <joint name="right_outer_knuckle_joint">
      <state_interface name="position" />
      <state_interface name="velocity" />
    </joint>
    <joint name="right_inner_knuckle_joint">
      <state_interface name="position" />
      <state_interface name="velocity" />
    </joint>
    <joint name="right_inner_finger_joint">
      <state_interface name="position" />
      <state_interface name="velocity" />
    </joint>
    <gpio name="reactivate_gripper">
      <command_interface name="reactivate_gripper_cmd" />
      <command_interface name="reactivate_gripper_response" />
    </gpio>
  </ros2_control>
  
  <link name="robotiq_base_link" />
  <link name="robotiq_140_base_link">
    <inertial>
      <origin rpy="0 0 0" xyz="8.625E-08 -4.6583E-06 0.03145" />
      <mass value="0.22652" />
      <inertia ixx="0.00020005" ixy="-4.2442E-10" ixz="-2.9069E-10" iyy="0.00017832" iyz="-3.4402E-08" izz="0.00013478" />
    </inertial>
    <visual>
      <origin rpy="0 0 0" xyz="0 0 0" />
      <geometry>
        <mesh filename="package://merge/mesh/2f-140/visual/robotiq_2f_140_base_link.stl" />
      </geometry>
      <material name="">
        <color rgba="0.1 0.1 0.1 1" />
      </material>
    </visual>
    <collision>
      <origin rpy="0 0 0" xyz="0 0 0" />
      <geometry>
        <mesh filename="package://merge/mesh/2f-140/collision/robotiq_2f_140_base_link.stl" />
      </geometry>
    </collision>
  </link>
  <joint name="robotiq_140_base_joint" type="fixed">
    <parent link="robotiq_base_link" />
    <child link="robotiq_140_base_link" />
    <origin rpy="0 0 0" xyz="0 0 0" />
  </joint>
  <link name="left_outer_knuckle">
    <inertial>
      <origin rpy="0 0 0" xyz="-0.000200000000003065 0.0199435877845359 0.0292245259211331" />
      <mass value="0.00853198276973456" />
      <inertia ixx="2.89328108496468E-06" ixy="-1.57935047237397E-19" ixz="-1.93980378593255E-19" iyy="1.86719750325683E-06" iyz="-1.21858577871576E-06" izz="1.21905238907251E-06" />
    </inertial>
    <visual>
      <origin rpy="0 0 0" xyz="0 0 0" />
      <geometry>
        <mesh filename="package://merge/mesh/2f-140/visual/robotiq_2f_140_outer_knuckle.stl" />
      </geometry>
      <material name="">
        <color rgba="0.792156862745098 0.819607843137255 0.933333333333333 1" />
      </material>
    </visual>
    <collision>
      <origin rpy="0 0 0" xyz="0 0 0" />
      <geometry>
        <mesh filename="package://merge/mesh/2f-140/collision/robotiq_2f_140_outer_knuckle.stl" />
      </geometry>
    </collision>
  </link>
  <link name="left_outer_finger">
    <inertial>
      <origin rpy="0 0 0" xyz="0.00030115855001899 0.0373907951953854 -0.0208027427000385" />
      <mass value="0.022614240507152" />
      <inertia ixx="1.52518312458174E-05" ixy="9.76583423954399E-10" ixz="-5.43838577022588E-10" iyy="6.17694243867776E-06" iyz="6.78636130740228E-06" izz="1.16494917907219E-05" />
    </inertial>
    <visual>
      <origin rpy="0 0 0" xyz="0 0 0" />
      <geometry>
        <mesh filename="package://merge/mesh/2f-140/visual/robotiq_2f_140_outer_finger.stl" />
      </geometry>
      <material name="">
        <color rgba="0.1 0.1 0.1 1" />
      </material>
    </visual>
    <collision>
      <origin rpy="0 0 0" xyz="0 0 0" />
      <geometry>
        <mesh filename="package://merge/mesh/2f-140/collision/robotiq_2f_140_outer_finger.stl" />
      </geometry>
    </collision>
  </link>
  <link name="left_inner_finger">
    <inertial>
      <origin rpy="0 0 0" xyz="0.000299999999999317 0.0160078233491243 -0.0136945669206257" />
      <mass value="0.0104003125914103" />
      <inertia ixx="2.71909453810972E-06" ixy="1.35402465472579E-21" ixz="-7.1817349065269E-22" iyy="7.69100314106116E-07" iyz="6.74715432769696E-07" izz="2.30315190420171E-06" />
    </inertial>
    <visual>
      <origin rpy="0 0 0" xyz="0 0 0" />
      <geometry>
        <mesh filename="package://merge/mesh/2f-140/visual/robotiq_2f_140_inner_finger.stl" />
      </geometry>
      <material name="">
        <color rgba="0.1 0.1 0.1 1" />
      </material>
    </visual>
    <collision>
      <origin rpy="0 0 0" xyz="0 0 0" />
      <geometry>
        <mesh filename="package://merge/mesh/2f-140/collision/robotiq_2f_140_inner_finger.stl" />
      </geometry>
    </collision>
  </link>
  <link name="left_inner_finger_pad">
    <visual>
      <origin rpy="0 0 0" xyz="0 0 0" />
      <geometry>
        <box size="0.027 0.065 0.0075" />
      </geometry>
      <material name="">
        <color rgba="0.9 0.9 0.9 1" />
      </material>
    </visual>
    <collision>
      <origin rpy="0 0 0" xyz="0 0 0" />
      <geometry>
        <box size="0.03 0.07 0.0075" />
      </geometry>
      <material name="">
        <color rgba="0.9 0.0 0.0 1" />
      </material>
    </collision>
  </link>
  <link name="left_inner_knuckle">
    <inertial>
      <origin rpy="0 0 0" xyz="0.000123011831763771 0.0507850843201817 0.00103968640075166" />
      <mass value="0.0271177346495152" />
      <inertia ixx="2.61910379223783E-05" ixy="-2.43616858946494E-07" ixz="-6.37789906117123E-09" iyy="2.8270243746167E-06" iyz="-5.37200748039765E-07" izz="2.83695868220296E-05" />
    </inertial>
    <visual>
      <origin rpy="0 0 0" xyz="0 0 0" />
      <geometry>
        <mesh filename="package://merge/mesh/2f-140/visual/robotiq_2f_140_inner_knuckle.stl" />
      </geometry>
      <material name="">
        <color rgba="0.1 0.1 0.1 1" />
      </material>
    </visual>
    <collision>
      <origin rpy="0 0 0" xyz="0 0 0" />
      <geometry>
        <mesh filename="package://merge/mesh/2f-140/collision/robotiq_2f_140_inner_knuckle.stl" />
      </geometry>
    </collision>
  </link>
  <link name="right_outer_knuckle">
    <inertial>
      <origin rpy="0 0 0" xyz="-0.000200000000003065 0.0199435877845359 0.0292245259211331" />
      <mass value="0.00853198276973456" />
      <inertia ixx="2.89328108496468E-06" ixy="-1.57935047237397E-19" ixz="-1.93980378593255E-19" iyy="1.86719750325683E-06" iyz="-1.21858577871576E-06" izz="1.21905238907251E-06" />
    </inertial>
    <visual>
      <origin rpy="0 0 0" xyz="0 0 0" />
      <geometry>
        <mesh filename="package://merge/mesh/2f-140/visual/robotiq_2f_140_outer_knuckle.stl" />
      </geometry>
      <material name="">
        <color rgba="0.792156862745098 0.819607843137255 0.933333333333333 1" />
      </material>
    </visual>
    <collision>
      <origin rpy="0 0 0" xyz="0 0 0" />
      <geometry>
        <mesh filename="package://merge/mesh/2f-140/collision/robotiq_2f_140_outer_knuckle.stl" />
      </geometry>
    </collision>
  </link>
  <link name="right_outer_finger">
    <inertial>
      <origin rpy="0 0 0" xyz="0.00030115855001899 0.0373907951953854 -0.0208027427000385" />
      <mass value="0.022614240507152" />
      <inertia ixx="1.52518312458174E-05" ixy="9.76583423954399E-10" ixz="-5.43838577022588E-10" iyy="6.17694243867776E-06" iyz="6.78636130740228E-06" izz="1.16494917907219E-05" />
    </inertial>
    <visual>
      <origin rpy="0 0 0" xyz="0 0 0" />
      <geometry>
        <mesh filename="package://merge/mesh/2f-140/visual/robotiq_2f_140_outer_finger.stl" />
      </geometry>
      <material name="">
        <color rgba="0.1 0.1 0.1 1" />
      </material>
    </visual>
    <collision>
      <origin rpy="0 0 0" xyz="0 0 0" />
      <geometry>
        <mesh filename="package://merge/mesh/2f-140/collision/robotiq_2f_140_outer_finger.stl" />
      </geometry>
    </collision>
  </link>
  <link name="right_inner_finger">
    <inertial>
      <origin rpy="0 0 0" xyz="0.000299999999999317 0.0160078233491243 -0.0136945669206257" />
      <mass value="0.0104003125914103" />
      <inertia ixx="2.71909453810972E-06" ixy="1.35402465472579E-21" ixz="-7.1817349065269E-22" iyy="7.69100314106116E-07" iyz="6.74715432769696E-07" izz="2.30315190420171E-06" />
    </inertial>
    <visual>
      <origin rpy="0 0 0" xyz="0 0 0" />
      <geometry>
        <mesh filename="package://merge/mesh/2f-140/visual/robotiq_2f_140_inner_finger.stl" />
      </geometry>
      <material name="">
        <color rgba="0.1 0.1 0.1 1" />
      </material>
    </visual>
    <collision>
      <origin rpy="0 0 0" xyz="0 0 0" />
      <geometry>
        <mesh filename="package://merge/mesh/2f-140/collision/robotiq_2f_140_inner_finger.stl" />
      </geometry>
    </collision>
  </link>
  <link name="right_inner_finger_pad">
    <visual>
      <origin rpy="0 0 0" xyz="0 0 0" />
      <geometry>
        <box size="0.027 0.065 0.0075" />
      </geometry>
      <material name="">
        <color rgba="0.9 0.9 0.9 1" />
      </material>
    </visual>
    <collision>
      <origin rpy="0 0 0" xyz="0 0 0" />
      <geometry>
        <box size="0.03 0.07 0.0075" />
      </geometry>
      <material name="">
        <color rgba="0.9 0.0 0.0 1" />
      </material>
    </collision>
  </link>
  <link name="right_inner_knuckle">
    <inertial>
      <origin rpy="0 0 0" xyz="0.000123011831763771 0.0507850843201817 0.00103968640075166" />
      <mass value="0.0271177346495152" />
      <inertia ixx="2.61910379223783E-05" ixy="-2.43616858946494E-07" ixz="-6.37789906117123E-09" iyy="2.8270243746167E-06" iyz="-5.37200748039765E-07" izz="2.83695868220296E-05" />
    </inertial>
    <visual>
      <origin rpy="0 0 0" xyz="0 0 0" />
      <geometry>
        <mesh filename="package://merge/mesh/2f-140/visual/robotiq_2f_140_inner_knuckle.stl" />
      </geometry>
      <material name="">
        <color rgba="0.1 0.1 0.1 1" />
      </material>
    </visual>
    <collision>
      <origin rpy="0 0 0" xyz="0 0 0" />
      <geometry>
        <mesh filename="package://merge/mesh/2f-140/collision/robotiq_2f_140_inner_knuckle.stl" />
      </geometry>
    </collision>
  </link>
  <joint name="finger_joint" type="revolute">
    <origin rpy="2.2957963267948966 0 0" xyz="0 -0.030601 0.054905" />
    <parent link="robotiq_140_base_link" />
    <child link="left_outer_knuckle" />
    <axis xyz="-1 0 0" />
    <limit effort="1000" lower="0" upper="0.7" velocity="2.0" />
  </joint>
  <joint name="left_outer_finger_joint" type="fixed">
    <origin rpy="0 0 0" xyz="0 0.01821998610742 0.0260018192872234" />
    <parent link="left_outer_knuckle" />
    <child link="left_outer_finger" />
    <axis xyz="1 0 0" />
  </joint>
  <joint name="left_inner_knuckle_joint" type="revolute">
    <origin rpy="2.2957963267948966 0 0.0" xyz="0 -0.0127 0.06142" />
    <parent link="robotiq_140_base_link" />
    <child link="left_inner_knuckle" />
    <axis xyz="1 0 0" />
    <limit effort="1000" lower="-0.8757" upper="0.8757" velocity="2.0" />
    <mimic joint="finger_joint" multiplier="-1" offset="0" />
  </joint>
  <joint name="left_inner_finger_joint" type="revolute">
    <origin rpy="-0.725 0 0" xyz="0 0.0817554015893473 -0.0282203446692936" />
    <parent link="left_outer_finger" />
    <child link="left_inner_finger" />
    <axis xyz="1 0 0" />
    <limit effort="1000" lower="-0.8757" upper="0.8757" velocity="2.0" />
    <mimic joint="finger_joint" multiplier="1" offset="0" />
  </joint>
  <joint name="left_inner_finger_pad_joint" type="fixed">
    <origin rpy="0 0 0" xyz="0 0.0457554015893473 -0.0272203446692936" />
    <parent link="left_inner_finger" />
    <child link="left_inner_finger_pad" />
    <axis xyz="0 0 1" />
  </joint>
  <joint name="right_outer_knuckle_joint" type="revolute">
    <origin rpy="2.2957963267948966 0 3.141592653589793" xyz="0 0.030601 0.054905" />
    <parent link="robotiq_140_base_link" />
    <child link="right_outer_knuckle" />
    <axis xyz="1 0 0" />
    <limit effort="1000" lower="-0.725" upper="0.725" velocity="2.0" />
    <mimic joint="finger_joint" multiplier="-1" offset="0" />
  </joint>
  <joint name="right_outer_finger_joint" type="fixed">
    <origin rpy="0 0 0" xyz="0 0.01821998610742 0.0260018192872234" />
    <parent link="right_outer_knuckle" />
    <child link="right_outer_finger" />
    <axis xyz="1 0 0" />
  </joint>
  <joint name="right_inner_knuckle_joint" type="revolute">
    <origin rpy="2.2957963267948966 0 -3.141592653589793" xyz="0 0.0127 0.06142" />
    <parent link="robotiq_140_base_link" />
    <child link="right_inner_knuckle" />
    <axis xyz="1 0 0" />
    <limit effort="1000" lower="-0.8757" upper="0.8757" velocity="2.0" />
    <mimic joint="finger_joint" multiplier="-1" offset="0" />
  </joint>
  <joint name="right_inner_finger_joint" type="revolute">
    <origin rpy="-0.725 0 0" xyz="0 0.0817554015893473 -0.0282203446692936" />
    <parent link="right_outer_finger" />
    <child link="right_inner_finger" />
    <axis xyz="1 0 0" />
    <limit effort="1000" lower="-0.8757" upper="0.8757" velocity="2.0" />
    <mimic joint="finger_joint" multiplier="1" offset="0" />
  </joint>
  <joint name="right_inner_finger_pad_joint" type="fixed">
    <origin rpy="0 0 0" xyz="0 0.0457554015893473 -0.0272203446692936" />
    <parent link="right_inner_finger" />
    <child link="right_inner_finger_pad" />
    <axis xyz="0 0 1" />
  </joint>
</robot>
