<?xml version="1.0" ?>
<!-- =================================================================================== -->
<!-- |    This document was autogenerated by xacro from xacro_models/square_hand.urdf.xacro | -->
<!-- |    EDITING THIS FILE BY HAND IS NOT RECOMMENDED                                 | -->
<!-- =================================================================================== -->
<robot name="mi_hand">
  <material name="aluminum">
    <color rgba="0.9 0.9 0.9 1"/>
  </material>
  <link name="base_link">
    <visual>
      <origin rpy="0 0 0" xyz="0 0 0"/>
      <geometry>
        <mesh filename="package://mi_hand_description/meshes/MH512502-00-000_V5.1-2_Base.stl"/>
      </geometry>
      <material name="aluminum"/>
    </visual>
  </link>
  <joint name="right_finger_link_joint" type="prismatic">
    <origin rpy="0 0 0" xyz="0 0 0"/>
    <parent link="base_link"/>
    <child link="right_finger_link"/>
    <axis xyz="0 1 0"/>
  </joint>
  <link name="right_finger_link">
    <visual>
      <origin rpy="0 0 3.141592" xyz="0 0 0.15212"/>
      <geometry>
        <mesh filename="package://mi_hand_description/meshes/MH512507-03-000-4_V5.1-4_25.9.8.stl"/>
      </geometry>
      <material name="aluminum"/>
    </visual>
  </link>
  <joint name="left_finger_link_joint" type="prismatic">
    <origin rpy="0 0 0" xyz="0 0 0"/>
    <parent link="base_link"/>
    <child link="left_finger_link"/>
    <axis xyz="0 1 0"/>
  </joint>
  <link name="left_finger_link">
    <visual>
      <origin rpy="0 0 0" xyz="0 0 0.15212"/>
      <geometry>
        <mesh filename="package://mi_hand_description/meshes/MH512507-03-000-4_V5.1-4_25.9.8.stl"/>
      </geometry>
      <material name="aluminum"/>
    </visual>
  </link>
  <joint name="tcp_link_joint" type="fixed">
    <origin rpy="0 0 0" xyz="0 0 0.455"/>
    <parent link="base_link"/>
    <child link="tcp_link"/>
  </joint>
  <link name="tcp_link"/>
</robot>
